Workbook

Sheet SUNDAY ATTENDANCE
B1: SUNDAY SERVICE ATTENDANCE ROLL CALL ANALYSIS
A3: S/N | B3: NAMES OF MEMBERS | C3: JANUARY
A4: 1 | B4: =GENERAL!B8 -> REV. DR. OSAZE GREAT-ZION, 08188591715; [GO Headquarters]; [Men of Impact] | C4: 1
A7: 2 | B7: =GENERAL!B11 -> REV. MRS. EDOSA GREAT-ZION; 08034701063; [President, Women of Purpose] | C7: =SUM(GENERAL!H11,GENERAL!L11,GENERAL!P11,GENERAL!T11,GENERAL!X11) -> 0
A10: 3 | B10: =GENERAL!B14 -> PST. RALPH, 08163941615; [EGEDE Extension Pastor]; [Men of Impact] | C10: =SUM(GENERAL!H14,GENERAL!L14,GENERAL!P14,GENERAL!T14,GENERAL!X14) -> 0
A13: 4 | B13: =GENERAL!B17 -> PST. ROMANUS I, 09034788649; [Eweka Extension Pastor]; [Men of Impact] | C13: =SUM(GENERAL!H17,GENERAL!L17,GENERAL!P17,GENERAL!T17,GENERAL!X17) -> 0
A16: 5 | B16: =GENERAL!B20 -> PST. SAMUEL, 08066314143; [Extension Pastor]; [Men of Impact] | C16: =SUM(GENERAL!H20,GENERAL!L20,GENERAL!P20,GENERAL!T20,GENERAL!X20) -> 0
A19: 6 | B19: =GENERAL!B23 -> DCN. ESTON 08034747107; [Eweka Extension]; [Men of Impact] | C19: =SUM(GENERAL!I25,GENERAL!M25,GENERAL!Q25,GENERAL!U25) -> 0
A22: 7 | B22: =GENERAL!B26 -> DCN. ABEL 08131940031; [GRA Extension]; [Men of Impact] | C22: =SUM(GENERAL!I28,GENERAL!M28,GENERAL!Q28,GENERAL!U28) -> 0
A25: 8 | B25: =GENERAL!B29 -> DCN SAM. O 08151215991; [Headquarters, Deacon]; [Men of Impact] | C25: =SUM(GENERAL!I31,GENERAL!M31,GENERAL!Q31,GENERAL!U31) -> 0
A28: 9 | B28: =GENERAL!B32 -> BRO. JULIUS IMHANA 08108372149; [Headquarters, Men of Impact Chairman]; [Men of Impact] | C28: =SUM(GENERAL!I34,GENERAL!M34,GENERAL!Q34,GENERAL!U34) -> 0
A31: 10 | B31: =GENERAL!B35 -> BRO. MATTHEW 07053928408: [Headquarters Member]; [Men of Impact] | C31: =SUM(GENERAL!I37,GENERAL!M37,GENERAL!Q37,GENERAL!U37) -> 0
A34: 11 | B34: =GENERAL!B38 -> BRO. WISDOM 08066120841: [Headquarters Member]; [Men of Impact] | C34: =SUM(GENERAL!I40,GENERAL!M40,GENERAL!Q40,GENERAL!U40) -> 0
A37: 12 | B37: =GENERAL!B41 -> BRO. GODWIN 07059776499: [Headquarters Member]; [Men of Impact] | C37: =SUM(GENERAL!I43,GENERAL!M43,GENERAL!Q43,GENERAL!U43) -> 0
A40: 13 | B40: =GENERAL!B44 -> BRO. ALEX KENNEDY 08060299070: [Headquarters Member]; [Men of Impact] | C40: =SUM(GENERAL!I46,GENERAL!M46,GENERAL!Q46,GENERAL!U46) -> 2
A43: 14 | B43: =GENERAL!B47 -> BRO. CHARLES 08051921359: [Headquarters Member]; [Men of Impact] | C43: =SUM(GENERAL!I49,GENERAL!M49,GENERAL!Q49,GENERAL!U49) -> 0
A46: 15 | B46: =GENERAL!B49 -> BRO. DANIEL 08108460601: [Headquarters Member]; [Men of Impact] | C46: =SUM(GENERAL!I73,GENERAL!M73,GENERAL!Q73,GENERAL!U73) -> 0
A49: 16 | B49: =GENERAL!B52 -> BRO. UZOMA 09025797913: [Headquarters Member]; [Men of Impact] | C49: =SUM(GENERAL!I54,GENERAL!M54,GENERAL!Q54,GENERAL!U54,GENERAL!X52) -> 2
A52: 17 | B52: =GENERAL!B55 -> BRO. ESOSA I 08058235675: [Headquarters Member]; [Men of Impact] | C52: =SUM(GENERAL!I57,GENERAL!M57,GENERAL!Q57,GENERAL!U57) -> 2
A55: 18 | B55: =GENERAL!B58 -> BRO. PAUL ASEMOTA. 08092033463: [Headquarters Member]; [Men of Impact] | C55: =SUM(GENERAL!I60,GENERAL!M60,GENERAL!Q60,GENERAL!U60) -> 1
A58: 19 | B58: =GENERAL!B61 -> BRO. SAMUEL ETIM 07070256353: [Headquarters Member]; [Men of Impact] | C58: =SUM(GENERAL!I63,GENERAL!M63,GENERAL!Q63,GENERAL!U63) -> 0
A61: 20 | B61: =GENERAL!B64 -> BRO. SUNNY K. 08035981524: [Headquarters Member]; [Men of Impact] | C61: =SUM(GENERAL!I66,GENERAL!M66,GENERAL!Q66,GENERAL!U66) -> 0
A64: 21 | B64: =GENERAL!B67 -> BRO. PETER AIGBE 08077625088: [Headquarters Member]; [Men of Impact] | C64: =SUM(GENERAL!I69,GENERAL!M69,GENERAL!Q69,GENERAL!U69) -> 0
A67: 22 | B67: =GENERAL!B70 -> BRO. SUNNY I 09067583446: [Headquarters Member]; [Men of Impact] | C67: =SUM(GENERAL!I72,GENERAL!M72,GENERAL!Q72,GENERAL!U72) -> 0
A70: 23 | B70: =GENERAL!B77 -> BRO. MONDAY 09077277209: [Headquarters Member]; [Men of Impact] | C70: =SUM(GENERAL!I79,GENERAL!M79,GENERAL!Q79,GENERAL!U79) -> 0
A73: 24 | B73: =GENERAL!B80 -> BRO. STEVE AGWEBOR 08143169535: [Headquarters Member]; [Men of Impact] | C73: =SUM(GENERAL!I82,GENERAL!M82,GENERAL!Q82,GENERAL!U82) -> 0
A76: 25 | B76: =GENERAL!B83 -> BRO. EFOSA 07036845256: [Headquarters Member]; [Men of Impact] | C76: =SUM(GENERAL!I85,GENERAL!M85,GENERAL!Q85,GENERAL!U85) -> 0
A79: 26 | B79: =GENERAL!B86 -> BRO. THANK-GOD 08111573236: [Headquarters Member]; [Men of Impact] | C79: =SUM(GENERAL!I85,GENERAL!M85,GENERAL!Q85,GENERAL!U85) -> 0
A82: 27 | B82: =GENERAL!B89 -> BRO. HAPPY I. 08078378791: [Headquarters Member]; [Men of Impact] | C82: =SUM(GENERAL!I91,GENERAL!M91,GENERAL!Q91,GENERAL!U91) -> 2
A85: 28 | B85: =GENERAL!B92 -> BRO. VICTOR 08168554928; [Headquarters, Member]; [Men of Impact] | C85: =SUM(GENERAL!I91,GENERAL!M91,GENERAL!Q91,GENERAL!U91) -> 2
A88: 29 | B88: =GENERAL!B95 -> BRO. GOODNEWS 08164992804: [Headquarters Member]; [Men of Impact] | C88: =SUM(GENERAL!I97,GENERAL!M97,GENERAL!Q97,GENERAL!U97) -> 1
A91: 30 | B91: =GENERAL!B98 -> BRO. SAMUEL 08139968749: [Headquarters Member]; [Men of Impact] | C91: =SUM(GENERAL!I100,GENERAL!M100,GENERAL!Q100,GENERAL!U100) -> 2
A94: 31 | B94: =GENERAL!B101 -> BRO. WISDOM CHIBUIKE 08059091960: [Headquarters Member]; [Men of Impact] | C94: =SUM(GENERAL!I103,GENERAL!M103,GENERAL!Q103,GENERAL!U103,GENERAL!Y103) -> 2
A97: 32 | B97: =GENERAL!B104 -> BRO. EPA AKPE 08039469795: [Headquarters Member]; [Men of Impact] | C97: =SUM(GENERAL!I106,GENERAL!M106,GENERAL!Q106,GENERAL!U106) -> 2
A100: 33 | B100: =GENERAL!B107 -> BRO. SOLOMON 08066599049: [Headquarters Member]; [Men of Impact] | C100: =SUM(GENERAL!I109,GENERAL!M109,GENERAL!Q109,GENERAL!U109) -> 0
A103: 34 | B103: =GENERAL!B110 -> BRO. PIUS 09032841227: [Headquarters Member]; [Men of Impact] | C103: =SUM(GENERAL!I112,GENERAL!M112,GENERAL!Q112,GENERAL!U112,GENERAL!Y112) -> 2
A106: 35 | B106: =GENERAL!B113 -> BRO. SAMUEL ETIM 07070256353: [Headquarters Member]; [Men of Impact] | C106: =SUM(GENERAL!I115,GENERAL!M115,GENERAL!Q115,GENERAL!U115) -> 0
A109: 39 | B109: =GENERAL!B116 -> BRO. I.K NJOKU 09153383840: [Headquarters Member]; [Men of Impact] | C109: =SUM(GENERAL!I118,GENERAL!M118,GENERAL!Q118,GENERAL!U118) -> 1
A112: 40 | B112: =GENERAL!B119 -> BRO. STANLEY UKEAGBU 08114510462: [Headquarters Member]; [Men of Impact] | C112: =SUM(GENERAL!I121,GENERAL!M121,GENERAL!Q121,GENERAL!U121) -> 0
A115: 42 | B115: =GENERAL!B122 -> BRO. EHIS O. 08148808661: [Headquarters Member]; [Men of Impact] | C115: =SUM(GENERAL!I124,GENERAL!M124,GENERAL!Q124,GENERAL!U124,GENERAL!Y124) -> 2
...

Sheet GENERAL
A1: , | B1: SPIRIT REALM CENTRE SUNDAY SERVICE ATTENDANCE TRACKER 2025
J2: PRESENT: | L2: ABSENT:
J3: ✔ | L3: A
B6: MEMBER'S INFORMATION | F6: 1ST SUN. 5/01/2025 | J6: 2ND SUN. 12/01/2025 | N6: 3RD SUN. 19/01/2025 | R6: 4TH SUN. 26/01/2025 | V6: 5TH SUN. 00/02/2025
A8: 1 | B8: REV. DR. OSAZE GREAT-ZION, 08188591715; [GO Headquarters]; [Men of Impact]
F10: Present: | G10: =COUNTIF(F8:G9,"✔") -> 0 | H10: Absent: | I10: =COUNTIF(H8:I9,"a") -> 0 | J10: Present: | K10: =COUNTIF(J8:K9,"✔") -> 0 | L10: Absent: | M10: =COUNTIF(L8:M9,"a") -> 0 | N10: Present: | O10: =COUNTIF(N8:O9,"✔") -> 0 | P10: Absent: | Q10: =COUNTIF(P8:Q9,"a") -> 0 | R10: Present: | S10: =COUNTIF(R8:S9,"✔") -> 0 | T10: Absent: | U10: =COUNTIF(T8:U9,"a") -> 0 | V10: Present: | W10: =COUNTIF(V8:W9,"✔") -> 0 | X10: Absent: | Y10: =COUNTIF(X8:Y9,"a") -> 0
A11: 2 | B11: REV. MRS. EDOSA GREAT-ZION; 08034701063; [President, Women of Purpose]
F13: Present: | G13: =COUNTIF(F11:G12,"✔") -> 0 | H13: Absent: | I13: =COUNTIF(H11:I12,"a") -> 0 | J13: Present: | K13: =COUNTIF(J11:K12,"✔") -> 0 | L13: Absent: | M13: =COUNTIF(L11:M12,"a") -> 0 | N13: Present: | O13: =COUNTIF(N11:O12,"✔") -> 0 | P13: Absent: | Q13: =COUNTIF(P11:Q12,"a") -> 0 | R13: Present: | S13: =COUNTIF(R11:S12,"✔") -> 0 | T13: Absent: | U13: =COUNTIF(T11:U12,"a") -> 0 | V13: Present: | W13: =COUNTIF(V11:W12,"✔") -> 0 | X13: Absent: | Y13: =COUNTIF(X11:Y12,"a") -> 0
A14: 3 | B14: PST. RALPH, 08163941615; [EGEDE Extension Pastor]; [Men of Impact]
F16: Present: | G16: =COUNTIF(F14:G15,"✔") -> 0 | H16: Absent: | I16: =COUNTIF(H14:I15,"a") -> 0 | J16: Present: | K16: =COUNTIF(J14:K15,"✔") -> 0 | L16: Absent: | M16: =COUNTIF(L14:M15,"a") -> 0 | N16: Present: | O16: =COUNTIF(N14:O15,"✔") -> 0 | P16: Absent: | Q16: =COUNTIF(P14:Q15,"a") -> 0 | R16: Present: | S16: =COUNTIF(R14:S15,"✔") -> 0 | T16: Absent: | U16: =COUNTIF(T14:U15,"a") -> 0 | V16: Present: | W16: =COUNTIF(V14:W15,"✔") -> 0 | X16: Absent: | Y16: =COUNTIF(X14:Y15,"a") -> 0
A17: 4 | B17: PST. ROMANUS I, 09034788649; [Eweka Extension Pastor]; [Men of Impact]
F19: Present: | G19: =COUNTIF(F17:G18,"✔") -> 0 | H19: Absent: | I19: =COUNTIF(H17:I18,"a") -> 0 | J19: Present: | K19: =COUNTIF(J17:K18,"✔") -> 0 | L19: Absent: | M19: =COUNTIF(L17:M18,"a") -> 0 | N19: Present: | O19: =COUNTIF(N17:O18,"✔") -> 0 | P19: Absent: | Q19: =COUNTIF(P17:Q18,"a") -> 0 | R19: Present: | S19: =COUNTIF(R17:S18,"✔") -> 0 | T19: Absent: | U19: =COUNTIF(T17:U18,"a") -> 0 | V19: Present: | W19: =COUNTIF(V17:W18,"✔") -> 0 | X19: Absent: | Y19: =COUNTIF(X17:Y18,"a") -> 0
B20: PST. SAMUEL, 08066314143; [Extension Pastor]; [Men of Impact]
F22: Present: | G22: =COUNTIF(F20:G21,"✔") -> 0 | H22: Absent: | I22: =COUNTIF(H20:I21,"a") -> 0 | J22: Present: | K22: =COUNTIF(J20:K21,"✔") -> 0 | L22: Absent: | M22: =COUNTIF(L20:M21,"a") -> 0 | N22: Present: | O22: =COUNTIF(N20:O21,"✔") -> 0 | P22: Absent: | Q22: =COUNTIF(P20:Q21,"a") -> 0 | R22: Present: | S22: =COUNTIF(R20:S21,"✔") -> 0 | T22: Absent: | U22: =COUNTIF(T20:U21,"a") -> 0 | V22: Present: | W22: =COUNTIF(V20:W21,"✔") -> 0 | X22: Absent: | Y22: =COUNTIF(X20:Y21,"a") -> 0
B23: DCN. ESTON 08034747107; [Eweka Extension]; [Men of Impact]
F25: Present: | G25: =COUNTIF(F23:G24,"✔") -> 0 | H25: Absent: | I25: =COUNTIF(H23:I24,"a") -> 0 | J25: Present: | K25: =COUNTIF(J23:K24,"✔") -> 0 | L25: Absent: | M25: =COUNTIF(L23:M24,"a") -> 0 | N25: Present: | O25: =COUNTIF(N23:O24,"✔") -> 0 | P25: Absent: | Q25: =COUNTIF(P23:Q24,"a") -> 0 | R25: Present: | S25: =COUNTIF(R23:S24,"✔") -> 0 | T25: Absent: | U25: =COUNTIF(T23:U24,"a") -> 0 | V25: Present: | W25: =COUNTIF(V23:W24,"✔") -> 0 | X25: Absent: | Y25: =COUNTIF(X23:Y24,"a") -> 0
B26: DCN. ABEL 08131940031; [GRA Extension]; [Men of Impact]
F28: Present: | G28: =COUNTIF(F26:G27,"✔") -> 0 | H28: Absent: | I28: =COUNTIF(H26:I27,"a") -> 0 | J28: Present: | K28: =COUNTIF(J26:K27,"✔") -> 0 | L28: Absent: | M28: =COUNTIF(L26:M27,"a") -> 0 | N28: Present: | O28: =COUNTIF(N26:O27,"✔") -> 0 | P28: Absent: | Q28: =COUNTIF(P26:Q27,"a") -> 0 | R28: Present: | S28: =COUNTIF(R26:S27,"✔") -> 0 | T28: Absent: | U28: =COUNTIF(T26:U27,"a") -> 0 | V28: Present: | W28: =COUNTIF(V26:W27,"✔") -> 0 | X28: Absent: | Y28: =COUNTIF(X26:Y27,"a") -> 0
B29: DCN SAM. O 08151215991; [Headquarters, Deacon]; [Men of Impact]
F31: Present: | G31: =COUNTIF(F29:G30,"✔") -> 0 | H31: Absent: | I31: =COUNTIF(H29:I30,"a") -> 0 | J31: Present: | K31: =COUNTIF(J29:K30,"✔") -> 0 | L31: Absent: | M31: =COUNTIF(L29:M30,"a") -> 0 | N31: Present: | O31: =COUNTIF(N29:O30,"✔") -> 0 | P31: Absent: | Q31: =COUNTIF(P29:Q30,"a") -> 0 | R31: Present: | S31: =COUNTIF(R29:S30,"✔") -> 0 | T31: Absent: | U31: =COUNTIF(T29:U30,"a") -> 0 | V31: Present: | W31: =COUNTIF(V29:W30,"✔") -> 0 | X31: Absent: | Y31: =COUNTIF(X29:Y30,"a") -> 0
B32: BRO. JULIUS IMHANA 08108372149; [Headquarters, Men of Impact Chairman]; [Men of Impact]
F34: Present: | G34: =COUNTIF(F32:G33,"✔") -> 0 | H34: Absent: | I34: =COUNTIF(H32:I33,"a") -> 0 | J34: Present: | K34: =COUNTIF(J32:K33,"✔") -> 0 | L34: Absent: | M34: =COUNTIF(L32:M33,"a") -> 0 | N34: Present: | O34: =COUNTIF(N32:O33,"✔") -> 0 | P34: Absent: | Q34: =COUNTIF(P32:Q33,"a") -> 0 | R34: Present: | S34: =COUNTIF(R32:S33,"✔") -> 0 | T34: Absent: | U34: =COUNTIF(T32:U33,"a") -> 0 | V34: Present: | W34: =COUNTIF(V32:W33,"✔") -> 0 | X34: Absent: | Y34: =COUNTIF(X32:Y33,"a") -> 0
B35: BRO. MATTHEW 07053928408: [Headquarters Member]; [Men of Impact]
F37: Present: | G37: =COUNTIF(F35:G36,"✔") -> 0 | H37: Absent: | I37: =COUNTIF(H35:I36,"a") -> 0 | J37: Present: | K37: =COUNTIF(J35:K36,"✔") -> 0 | L37: Absent: | M37: =COUNTIF(L35:M36,"a") -> 0 | N37: Present: | O37: =COUNTIF(N35:O36,"✔") -> 0 | P37: Absent: | Q37: =COUNTIF(P35:Q36,"a") -> 0 | R37: Present: | S37: =COUNTIF(R35:S36,"✔") -> 0 | T37: Absent: | U37: =COUNTIF(T35:U36,"a") -> 0 | V37: Present: | W37: =COUNTIF(V35:W36,"✔") -> 0 | X37: Absent: | Y37: =COUNTIF(X35:Y36,"a") -> 0
B38: BRO. WISDOM 08066120841: [Headquarters Member]; [Men of Impact]
F40: Present: | G40: =COUNTIF(F38:G39,"✔") -> 0 | H40: Absent: | I40: =COUNTIF(H38:I39,"a") -> 0 | J40: Present: | K40: =COUNTIF(J38:K39,"✔") -> 0 | L40: Absent: | M40: =COUNTIF(L38:M39,"a") -> 0 | N40: Present: | O40: =COUNTIF(N38:O39,"✔") -> 0 | P40: Absent: | Q40: =COUNTIF(P38:Q39,"a") -> 0 | R40: Present: | S40: =COUNTIF(R38:S39,"✔") -> 0 | T40: Absent: | U40: =COUNTIF(T38:U39,"a") -> 0 | V40: Present: | W40: =COUNTIF(V38:W39,"✔") -> 0 | X40: Absent: | Y40: =COUNTIF(X38:Y39,"a") -> 0
B41: BRO. GODWIN 07059776499: [Headquarters Member]; [Men of Impact]
F43: Present: | G43: =COUNTIF(F41:G42,"✔") -> 0 | H43: Absent: | I43: =COUNTIF(H41:I42,"a") -> 0 | J43: Present: | K43: =COUNTIF(J41:K42,"✔") -> 0 | L43: Absent: | M43: =COUNTIF(L41:M42,"a") -> 0 | N43: Present: | O43: =COUNTIF(N41:O42,"✔") -> 0 | P43: Absent: | Q43: =COUNTIF(P41:Q42,"a") -> 0 | R43: Present: | S43: =COUNTIF(R41:S42,"✔") -> 0 | T43: Absent: | U43: =COUNTIF(T41:U42,"a") -> 0 | V43: Present: | W43: =COUNTIF(V41:W42,"✔") -> 0 | X43: Absent: | Y43: =COUNTIF(X41:Y42,"a") -> 0
B44: BRO. ALEX KENNEDY 08060299070: [Headquarters Member]; [Men of Impact] | H44: A | L44: A
F46: Present: | G46: =COUNTIF(F44:G45,"✔") -> 0 | H46: Absent: | I46: =COUNTIF(H44:I45,"a") -> 1 | J46: Present: | K46: =COUNTIF(J44:K45,"✔") -> 0 | L46: Absent: | M46: =COUNTIF(L44:M45,"a") -> 1 | N46: Present: | O46: =COUNTIF(N44:O45,"✔") -> 0 | P46: Absent: | Q46: =COUNTIF(P44:Q45,"a") -> 0 | R46: Present: | S46: =COUNTIF(R44:S45,"✔") -> 0 | T46: Absent: | U46: =COUNTIF(T44:U45,"a") -> 0 | V46: Present: | W46: =COUNTIF(V44:W45,"✔") -> 0 | X46: Absent: | Y46: =COUNTIF(X44:Y45,"a") -> 0
B47: BRO. CHARLES 08051921359: [Headquarters Member]; [Men of Impact]
B49: BRO. DANIEL 08108460601: [Headquarters Member]; [Men of Impact] | F49: Present: | G49: =COUNTIF(F47:G48,"✔") -> 0 | H49: Absent: | I49: =COUNTIF(H47:I48,"a") -> 0 | J49: Present: | K49: =COUNTIF(J47:K48,"✔") -> 0 | L49: Absent: | M49: =COUNTIF(L47:M48,"a") -> 0 | N49: Present: | O49: =COUNTIF(N47:O48,"✔") -> 0 | P49: Absent: | Q49: =COUNTIF(P47:Q48,"a") -> 0 | R49: Present: | S49: =COUNTIF(R47:S48,"✔") -> 0 | T49: Absent: | U49: =COUNTIF(T47:U48,"a") -> 0 | V49: Present: | W49: =COUNTIF(V47:W48,"✔") -> 0 | X49: Absent: | Y49: =COUNTIF(X47:Y48,"a") -> 0
B52: BRO. UZOMA 09025797913: [Headquarters Member]; [Men of Impact] | H52: A | L52: A
F54: Present: | G54: =COUNTIF(F52:G53,"✔") -> 0 | H54: Absent: | I54: =COUNTIF(H52:I53,"a") -> 1 | J54: Present: | K54: =COUNTIF(J52:K53,"✔") -> 0 | L54: Absent: | M54: =COUNTIF(L52:M53,"a") -> 1 | N54: Present: | O54: =COUNTIF(N52:O53,"✔") -> 0 | P54: Absent: | Q54: =COUNTIF(P52:Q53,"a") -> 0 | R54: Present: | S54: =COUNTIF(R52:S53,"✔") -> 0 | T54: Absent: | U54: =COUNTIF(T52:U53,"a") -> 0 | V54: Present: | W54: =COUNTIF(V52:W53,"✔") -> 0 | X54: Absent: | Y54: =COUNTIF(X52:Y53,"a") -> 0
B55: BRO. ESOSA I 08058235675: [Headquarters Member]; [Men of Impact] | H55: A | L55: A
F57: Present: | G57: =COUNTIF(F55:G56,"✔") -> 0 | H57: Absent: | I57: =COUNTIF(H55:I56,"a") -> 1 | J57: Present: | K57: =COUNTIF(J55:K56,"✔") -> 0 | L57: Absent: | M57: =COUNTIF(L55:M56,"a") -> 1 | N57: Present: | O57: =COUNTIF(N55:O56,"✔") -> 0 | P57: Absent: | Q57: =COUNTIF(P55:Q56,"a") -> 0 | R57: Present: | S57: =COUNTIF(R55:S56,"✔") -> 0 | T57: Absent: | U57: =COUNTIF(T55:U56,"a") -> 0 | V57: Present: | W57: =COUNTIF(V55:W56,"✔") -> 0 | X57: Absent: | Y57: =COUNTIF(X55:Y56,"a") -> 0
B58: BRO. PAUL ASEMOTA. 08092033463: [Headquarters Member]; [Men of Impact] | H58: A
F60: Present: | G60: =COUNTIF(F58:G59,"✔") -> 0 | H60: Absent: | I60: =COUNTIF(H58:I59,"a") -> 1 | J60: Present: | K60: =COUNTIF(J58:K59,"✔") -> 0 | L60: Absent: | M60: =COUNTIF(L58:M59,"a") -> 0 | N60: Present: | O60: =COUNTIF(N58:O59,"✔") -> 0 | P60: Absent: | Q60: =COUNTIF(P58:Q59,"a") -> 0 | R60: Present: | S60: =COUNTIF(R58:S59,"✔") -> 0 | T60: Absent: | U60: =COUNTIF(T58:U59,"a") -> 0 | V60: Present: | W60: =COUNTIF(V58:W59,"✔") -> 0 | X60: Absent: | Y60: =COUNTIF(X58:Y59,"a") -> 0
B61: BRO. SAMUEL ETIM 07070256353: [Headquarters Member]; [Men of Impact]
F63: Present: | G63: =COUNTIF(F61:G62,"✔") -> 0 | H63: Absent: | I63: =COUNTIF(H61:I62,"a") -> 0 | J63: Present: | K63: =COUNTIF(J61:K62,"✔") -> 0 | L63: Absent: | M63: =COUNTIF(L61:M62,"a") -> 0 | N63: Present: | O63: =COUNTIF(N61:O62,"✔") -> 0 | P63: Absent: | Q63: =COUNTIF(P61:Q62,"a") -> 0 | R63: Present: | S63: =COUNTIF(R61:S62,"✔") -> 0 | T63: Absent: | U63: =COUNTIF(T61:U62,"a") -> 0 | V63: Present: | W63: =COUNTIF(V61:W62,"✔") -> 0 | X63: Absent: | Y63: =COUNTIF(X61:Y62,"a") -> 0
...

Sheet MUSIC
B1: SPIRIT REALM CENTRE SUNDAY SERVICE ATTENDANCE TRACKER 2024
J2: PRESENT: | L2: ABSENT:
J3: ✔ | L3: A
B6: MEMBER'S INFORMATION | F6: 1ST SUN. 6/10/2024 | J6: 2ND SUN. 13/10/2024 | N6: 3RD SUN. 20/10/2024 | R6: 4TH SUN. 27/10/2024 | V6: 5 H SUN.
B8: NOSAKHARE BLESSING; 09050078657: [Headquarters Choir]; [Address]
F10: Present: | G10: =COUNTIF(F8:G9,"✔") -> 0 | H10: Absent: | I10: =COUNTIF(H8:I9,"a") -> 0 | J10: Present: | K10: =COUNTIF(J8:K9,"✔") -> 0 | L10: Absent: | M10: =COUNTIF(L8:M9,"a") -> 0 | N10: Present: | O10: =COUNTIF(N8:O9,"✔") -> 0 | P10: Absent: | Q10: =COUNTIF(P8:Q9,"a") -> 0 | R10: Present: | S10: =COUNTIF(R8:S9,"✔") -> 0 | T10: Absent: | U10: =COUNTIF(T8:U9,"a") -> 0 | V10: Present: | W10: =COUNTIF(V8:W9,"✔") -> 0 | X10: Absent: | Y10: =COUNTIF(X8:Y9,"a") -> 0
B11: OBAHOR BLESSING 09020677657: [Headquarters Choir]; [Address]
F13: Present: | G13: =COUNTIF(F11:G12,"✔") -> 0 | H13: Absent: | I13: =COUNTIF(H11:I12,"a") -> 0 | J13: Present: | K13: =COUNTIF(J11:K12,"✔") -> 0 | L13: Absent: | M13: =COUNTIF(L11:M12,"a") -> 0 | N13: Present: | O13: =COUNTIF(N11:O12,"✔") -> 0 | P13: Absent: | Q13: =COUNTIF(P11:Q12,"a") -> 0 | R13: Present: | S13: =COUNTIF(R11:S12,"✔") -> 0 | T13: Absent: | U13: =COUNTIF(T11:U12,"a") -> 0 | V13: Present: | W13: =COUNTIF(V11:W12,"✔") -> 0 | X13: Absent: | Y13: =COUNTIF(X11:Y12,"a") -> 0
B14: OTABOR BLESSING; 09156464691: [Headquarters Member]; [Choir]
F16: Present: | G16: =COUNTIF(F14:G15,"✔") -> 0 | H16: Absent: | I16: =COUNTIF(H14:I15,"a") -> 0 | J16: Present: | K16: =COUNTIF(J14:K15,"✔") -> 0 | L16: Absent: | M16: =COUNTIF(L14:M15,"a") -> 0 | N16: Present: | O16: =COUNTIF(N14:O15,"✔") -> 0 | P16: Absent: | Q16: =COUNTIF(P14:Q15,"a") -> 0 | R16: Present: | S16: =COUNTIF(R14:S15,"✔") -> 0 | T16: Absent: | U16: =COUNTIF(T14:U15,"a") -> 0 | V16: Present: | W16: =COUNTIF(V14:W15,"✔") -> 0 | X16: Absent: | Y16: =COUNTIF(X14:Y15,"a") -> 0
B17: OREDIA VICTORY; 08144836505: [Headquarters Member]; [Choir]
F19: Present: | G19: =COUNTIF(F17:G18,"✔") -> 0 | H19: Absent: | I19: =COUNTIF(H17:I18,"a") -> 0 | J19: Present: | K19: =COUNTIF(J17:K18,"✔") -> 0 | L19: Absent: | M19: =COUNTIF(L17:M18,"a") -> 0 | N19: Present: | O19: =COUNTIF(N17:O18,"✔") -> 0 | P19: Absent: | Q19: =COUNTIF(P17:Q18,"a") -> 0 | R19: Present: | S19: =COUNTIF(R17:S18,"✔") -> 0 | T19: Absent: | U19: =COUNTIF(T17:U18,"a") -> 0 | V19: Present: | W19: =COUNTIF(V17:W18,"✔") -> 0 | X19: Absent: | Y19: =COUNTIF(X17:Y18,"a") -> 0
B20: SIS COURAGE ATANE; 09052268276: [Headquarters Member]; [Choir]
F22: Present: | G22: =COUNTIF(F20:G21,"✔") -> 0 | H22: Absent: | I22: =COUNTIF(H20:I21,"a") -> 0 | J22: Present: | K22: =COUNTIF(J20:K21,"✔") -> 0 | L22: Absent: | M22: =COUNTIF(L20:M21,"a") -> 0 | N22: Present: | O22: =COUNTIF(N20:O21,"✔") -> 0 | P22: Absent: | Q22: =COUNTIF(P20:Q21,"a") -> 0 | R22: Present: | S22: =COUNTIF(R20:S21,"✔") -> 0 | T22: Absent: | U22: =COUNTIF(T20:U21,"a") -> 0 | V22: Present: | W22: =COUNTIF(V20:W21,"✔") -> 0 | X22: Absent: | Y22: =COUNTIF(X20:Y21,"a") -> 0
B23: ATANE JOY; 09165656493: [Headquarters Member]; [Choir]
F25: Present: | G25: =COUNTIF(F23:G24,"✔") -> 0 | H25: Absent: | I25: =COUNTIF(H23:I24,"a") -> 0 | J25: Present: | K25: =COUNTIF(J23:K24,"✔") -> 0 | L25: Absent: | M25: =COUNTIF(L23:M24,"a") -> 0 | N25: Present: | O25: =COUNTIF(N23:O24,"✔") -> 0 | P25: Absent: | Q25: =COUNTIF(P23:Q24,"a") -> 0 | R25: Present: | S25: =COUNTIF(R23:S24,"✔") -> 0 | T25: Absent: | U25: =COUNTIF(T23:U24,"a") -> 0 | V25: Present: | W25: =COUNTIF(V23:W24,"✔") -> 0 | X25: Absent: | Y25: =COUNTIF(X23:Y24,"a") -> 0
B26: SIS PRAISE ILEGBEJIE: [Headquarters Member]; [Choir]
F28: Present: | G28: =COUNTIF(F26:G27,"✔") -> 0 | H28: Absent: | I28: =COUNTIF(H26:I27,"a") -> 0 | J28: Present: | K28: =COUNTIF(J26:K27,"✔") -> 0 | L28: Absent: | M28: =COUNTIF(L26:M27,"a") -> 0 | N28: Present: | O28: =COUNTIF(N26:O27,"✔") -> 0 | P28: Absent: | Q28: =COUNTIF(P26:Q27,"a") -> 0 | R28: Present: | S28: =COUNTIF(R26:S27,"✔") -> 0 | T28: Absent: | U28: =COUNTIF(T26:U27,"a") -> 0 | V28: Present: | W28: =COUNTIF(V26:W27,"✔") -> 0 | X28: Absent: | Y28: =COUNTIF(X26:Y27,"a") -> 0
B29: SIS UGBEKILE FAITH; 0901216393: [Headquarters Member]; [Choir]
F31: Present: | G31: =COUNTIF(F29:G30,"✔") -> 0 | H31: Absent: | I31: =COUNTIF(H29:I30,"a") -> 0 | J31: Present: | K31: =COUNTIF(J29:K30,"✔") -> 0 | L31: Absent: | M31: =COUNTIF(L29:M30,"a") -> 0 | N31: Present: | O31: =COUNTIF(N29:O30,"✔") -> 0 | P31: Absent: | Q31: =COUNTIF(P29:Q30,"a") -> 0 | R31: Present: | S31: =COUNTIF(R29:S30,"✔") -> 0 | T31: Absent: | U31: =COUNTIF(T29:U30,"a") -> 0 | V31: Present: | W31: =COUNTIF(V29:W30,"✔") -> 0 | X31: Absent: | Y31: =COUNTIF(X29:Y30,"a") -> 0
B32: DESTINY (D.V); 07026612509: [Headquarters Member]; [Choir]
F34: Present: | G34: =COUNTIF(F32:G33,"✔") -> 0 | H34: Absent: | I34: =COUNTIF(H32:I33,"a") -> 0 | J34: Present: | K34: =COUNTIF(J32:K33,"✔") -> 0 | L34: Absent: | M34: =COUNTIF(L32:M33,"a") -> 0 | N34: Present: | O34: =COUNTIF(N32:O33,"✔") -> 0 | P34: Absent: | Q34: =COUNTIF(P32:Q33,"a") -> 0 | R34: Present: | S34: =COUNTIF(R32:S33,"✔") -> 0 | T34: Absent: | U34: =COUNTIF(T32:U33,"a") -> 0 | V34: Present: | W34: =COUNTIF(V32:W33,"✔") -> 0 | X34: Absent: | Y34: =COUNTIF(X32:Y33,"a") -> 0
B35: TRUST; 08117028203: [Headquarters Member]; [Choir]
F37: Present: | G37: =COUNTIF(F35:G36,"✔") -> 0 | H37: Absent: | I37: =COUNTIF(H35:I36,"a") -> 0 | J37: Present: | K37: =COUNTIF(J35:K36,"✔") -> 0 | L37: Absent: | M37: =COUNTIF(L35:M36,"a") -> 0 | N37: Present: | O37: =COUNTIF(N35:O36,"✔") -> 0 | P37: Absent: | Q37: =COUNTIF(P35:Q36,"a") -> 0 | R37: Present: | S37: =COUNTIF(R35:S36,"✔") -> 0 | T37: Absent: | U37: =COUNTIF(T35:U36,"a") -> 0 | V37: Present: | W37: =COUNTIF(V35:W36,"✔") -> 0 | X37: Absent: | Y37: =COUNTIF(X35:Y36,"a") -> 0
B38: HAPPY EDAHOR: [Headquarters Member]; [Choir]
F40: Present: | G40: =COUNTIF(F38:G39,"✔") -> 0 | H40: Absent: | I40: =COUNTIF(H38:I39,"a") -> 0 | J40: Present: | K40: =COUNTIF(J38:K39,"✔") -> 0 | L40: Absent: | M40: =COUNTIF(L38:M39,"a") -> 0 | N40: Present: | O40: =COUNTIF(N38:O39,"✔") -> 0 | P40: Absent: | Q40: =COUNTIF(P38:Q39,"a") -> 0 | R40: Present: | S40: =COUNTIF(R38:S39,"✔") -> 0 | T40: Absent: | U40: =COUNTIF(T38:U39,"a") -> 0 | V40: Present: | W40: =COUNTIF(V38:W39,"✔") -> 0 | X40: Absent: | Y40: =COUNTIF(X38:Y39,"a") -> 0
B41: BRO OSAGIE: [Headquarters Choir]; [Address]
F43: Present: | G43: =COUNTIF(F41:G42,"✔") -> 0 | H43: Absent: | I43: =COUNTIF(H41:I42,"a") -> 0 | J43: Present: | K43: =COUNTIF(J41:K42,"✔") -> 0 | L43: Absent: | M43: =COUNTIF(L41:M42,"a") -> 0 | N43: Present: | O43: =COUNTIF(N41:O42,"✔") -> 0 | P43: Absent: | Q43: =COUNTIF(P41:Q42,"a") -> 0 | R43: Present: | S43: =COUNTIF(R41:S42,"✔") -> 0 | T43: Absent: | U43: =COUNTIF(T41:U42,"a") -> 0 | V43: Present: | W43: =COUNTIF(V41:W42,"✔") -> 0 | X43: Absent: | Y43: =COUNTIF(X41:Y42,"a") -> 0
B44: SIS PRAISE AIGBOSE: [Headquarters Member]; [Choir]
F46: Present: | G46: =COUNTIF(F44:G45,"✔") -> 0 | H46: Absent: | I46: =COUNTIF(H44:I45,"a") -> 0 | J46: Present: | K46: =COUNTIF(J44:K45,"✔") -> 0 | L46: Absent: | M46: =COUNTIF(L44:M45,"a") -> 0 | N46: Present: | O46: =COUNTIF(N44:O45,"✔") -> 0 | P46: Absent: | Q46: =COUNTIF(P44:Q45,"a") -> 0 | R46: Present: | S46: =COUNTIF(R44:S45,"✔") -> 0 | T46: Absent: | U46: =COUNTIF(T44:U45,"a") -> 0 | V46: Present: | W46: =COUNTIF(V44:W45,"✔") -> 0 | X46: Absent: | Y46: =COUNTIF(X44:Y45,"a") -> 0
B47: NOSA SPLENDOR ; 07031567546: [Headquarters Member]; [Choir]
F49: Present: | G49: =COUNTIF(F47:G48,"✔") -> 0 | H49: Absent: | I49: =COUNTIF(H47:I48,"a") -> 0 | J49: Present: | K49: =COUNTIF(J47:K48,"✔") -> 0 | L49: Absent: | M49: =COUNTIF(L47:M48,"a") -> 0 | N49: Present: | O49: =COUNTIF(N47:O48,"✔") -> 0 | P49: Absent: | Q49: =COUNTIF(P47:Q48,"a") -> 0 | R49: Present: | S49: =COUNTIF(R47:S48,"✔") -> 0 | T49: Absent: | U49: =COUNTIF(T47:U48,"a") -> 0 | V49: Present: | W49: =COUNTIF(V47:W48,"✔") -> 0 | X49: Absent: | Y49: =COUNTIF(X47:Y48,"a") -> 0
B50: DESTINY OSABOKAM; 07026612509: [Headquarters Member]; [Choir]
F52: Present: | G52: =COUNTIF(F50:G51,"✔") -> 0 | H52: Absent: | I52: =COUNTIF(H50:I51,"a") -> 0 | J52: Present: | K52: =COUNTIF(J50:K51,"✔") -> 0 | L52: Absent: | M52: =COUNTIF(L50:M51,"a") -> 0 | N52: Present: | O52: =COUNTIF(N50:O51,"✔") -> 0 | P52: Absent: | Q52: =COUNTIF(P50:Q51,"a") -> 0 | R52: Present: | S52: =COUNTIF(R50:S51,"✔") -> 0 | T52: Absent: | U52: =COUNTIF(T50:U51,"a") -> 0 | V52: Present: | W52: =COUNTIF(V50:W51,"✔") -> 0 | X52: Absent: | Y52: =COUNTIF(X50:Y51,"a") -> 0

Sheet USHERS
B1: SPIRIT REALM CENTRE SUNDAY SERVICE ATTENDANCE TRACKER 2024
J2: PRESENT: | L2: ABSENT:
J3: ✔ | L3: A
B6: MEMBER'S INFORMATION | F6: 1ST SUN. 6/10/2024 | J6: 2ND SUN. 13/10/2024 | N6: 3RD SUN. 20/10/2024 | R6: 4TH SUN. 27/10/2024 | V6: 5 H SUN.
B8: BRO BEST; 07065313405: [Headquarters Usher ]; [AFTER CORNER STONE CHURCH AMAGBA, BENIN CITY]
F10: Present: | G10: =COUNTIF(F8:G9,"✔") -> 0 | H10: Absent: | I10: =COUNTIF(H8:I9,"a") -> 0 | J10: Present: | K10: =COUNTIF(J8:K9,"✔") -> 0 | L10: Absent: | M10: =COUNTIF(L8:M9,"a") -> 0 | N10: Present: | O10: =COUNTIF(N8:O9,"✔") -> 0 | P10: Absent: | Q10: =COUNTIF(P8:Q9,"a") -> 0 | R10: Present: | S10: =COUNTIF(R8:S9,"✔") -> 0 | T10: Absent: | U10: =COUNTIF(T8:U9,"a") -> 0 | V10: Present: | W10: =COUNTIF(V8:W9,"✔") -> 0 | X10: Absent: | Y10: =COUNTIF(X8:Y9,"a") -> 0
B11: BRO MORRIS; 0903 350 1577: [Headquarters Usher]; [EVBIOBOGUN SAPELE ROAD, BENIN CITY]
F13: Present: | G13: =COUNTIF(F11:G12,"✔") -> 0 | H13: Absent: | I13: =COUNTIF(H11:I12,"a") -> 0 | J13: Present: | K13: =COUNTIF(J11:K12,"✔") -> 0 | L13: Absent: | M13: =COUNTIF(L11:M12,"a") -> 0 | N13: Present: | O13: =COUNTIF(N11:O12,"✔") -> 0 | P13: Absent: | Q13: =COUNTIF(P11:Q12,"a") -> 0 | R13: Present: | S13: =COUNTIF(R11:S12,"✔") -> 0 | T13: Absent: | U13: =COUNTIF(T11:U12,"a") -> 0 | V13: Present: | W13: =COUNTIF(V11:W12,"✔") -> 0 | X13: Absent: | Y13: =COUNTIF(X11:Y12,"a") -> 0
B14: BRO DANIEL; 0901 162 8531: [Headquarters Usher]; [EVBIOBOGUN SAPELE ROAD BENIN CITY]
F16: Present: | G16: =COUNTIF(F14:G15,"✔") -> 0 | H16: Absent: | I16: =COUNTIF(H14:I15,"a") -> 0 | J16: Present: | K16: =COUNTIF(J14:K15,"✔") -> 0 | L16: Absent: | M16: =COUNTIF(L14:M15,"a") -> 0 | N16: Present: | O16: =COUNTIF(N14:O15,"✔") -> 0 | P16: Absent: | Q16: =COUNTIF(P14:Q15,"a") -> 0 | R16: Present: | S16: =COUNTIF(R14:S15,"✔") -> 0 | T16: Absent: | U16: =COUNTIF(T14:U15,"a") -> 0 | V16: Present: | W16: =COUNTIF(V14:W15,"✔") -> 0 | X16: Absent: | Y16: =COUNTIF(X14:Y15,"a") -> 0
B17: BRO BRIGHT; 0805 215 5988: [Headquarters Usher]; [UNITY STREET OFF ERADIAWA / SAPELE ROAD BENIN CITY]
F19: Present: | G19: =COUNTIF(F17:G18,"✔") -> 0 | H19: Absent: | I19: =COUNTIF(H17:I18,"a") -> 0 | J19: Present: | K19: =COUNTIF(J17:K18,"✔") -> 0 | L19: Absent: | M19: =COUNTIF(L17:M18,"a") -> 0 | N19: Present: | O19: =COUNTIF(N17:O18,"✔") -> 0 | P19: Absent: | Q19: =COUNTIF(P17:Q18,"a") -> 0 | R19: Present: | S19: =COUNTIF(R17:S18,"✔") -> 0 | T19: Absent: | U19: =COUNTIF(T17:U18,"a") -> 0 | V19: Present: | W19: =COUNTIF(V17:W18,"✔") -> 0 | X19: Absent: | Y19: =COUNTIF(X17:Y18,"a") -> 0
B20: BRO SUNDAY; 0906 758 3446: [Headquarters Usher]; [OFF OKHABARE SAPELE ROAD BENIN CITY]
F22: Present: | G22: =COUNTIF(F20:G21,"✔") -> 0 | H22: Absent: | I22: =COUNTIF(H20:I21,"a") -> 0 | J22: Present: | K22: =COUNTIF(J20:K21,"✔") -> 0 | L22: Absent: | M22: =COUNTIF(L20:M21,"a") -> 0 | N22: Present: | O22: =COUNTIF(N20:O21,"✔") -> 0 | P22: Absent: | Q22: =COUNTIF(P20:Q21,"a") -> 0 | R22: Present: | S22: =COUNTIF(R20:S21,"✔") -> 0 | T22: Absent: | U22: =COUNTIF(T20:U21,"a") -> 0 | V22: Present: | W22: =COUNTIF(V20:W21,"✔") -> 0 | X22: Absent: | Y22: =COUNTIF(X20:Y21,"a") -> 0
B23: BRO SUNNY; 0904 982 9594: [Headquarters Usher]; [ALONG ERADIAWA SAPKONBA ROAD BENIN CITY]
F25: Present: | G25: =COUNTIF(F23:G24,"✔") -> 0 | H25: Absent: | I25: =COUNTIF(H23:I24,"a") -> 0 | J25: Present: | K25: =COUNTIF(J23:K24,"✔") -> 0 | L25: Absent: | M25: =COUNTIF(L23:M24,"a") -> 0 | N25: Present: | O25: =COUNTIF(N23:O24,"✔") -> 0 | P25: Absent: | Q25: =COUNTIF(P23:Q24,"a") -> 0 | R25: Present: | S25: =COUNTIF(R23:S24,"✔") -> 0 | T25: Absent: | U25: =COUNTIF(T23:U24,"a") -> 0 | V25: Present: | W25: =COUNTIF(V23:W24,"✔") -> 0 | X25: Absent: | Y25: =COUNTIF(X23:Y24,"a") -> 0
B26: BRO GODWIN; 0705 977 6499: [Headquarters Usher]; [UROHO COMMUNITY OFF SAPELE ROAD BYPASS BENIN CITY]
F28: Present: | G28: =COUNTIF(F26:G27,"✔") -> 0 | H28: Absent: | I28: =COUNTIF(H26:I27,"a") -> 0 | J28: Present: | K28: =COUNTIF(J26:K27,"✔") -> 0 | L28: Absent: | M28: =COUNTIF(L26:M27,"a") -> 0 | N28: Present: | O28: =COUNTIF(N26:O27,"✔") -> 0 | P28: Absent: | Q28: =COUNTIF(P26:Q27,"a") -> 0 | R28: Present: | S28: =COUNTIF(R26:S27,"✔") -> 0 | T28: Absent: | U28: =COUNTIF(T26:U27,"a") -> 0 | V28: Present: | W28: =COUNTIF(V26:W27,"✔") -> 0 | X28: Absent: | Y28: =COUNTIF(X26:Y27,"a") -> 0
B29: BRO GOD'SPOWER; 09011402472: [Headquarters Usher]; [OFF 2ND ERADIAWA LANE, ALONG ERADIAWA SAPELE ROAD, BENIN CITY]
F31: Present: | G31: =COUNTIF(F29:G30,"✔") -> 0 | H31: Absent: | I31: =COUNTIF(H29:I30,"a") -> 0 | J31: Present: | K31: =COUNTIF(J29:K30,"✔") -> 0 | L31: Absent: | M31: =COUNTIF(L29:M30,"a") -> 0 | N31: Present: | O31: =COUNTIF(N29:O30,"✔") -> 0 | P31: Absent: | Q31: =COUNTIF(P29:Q30,"a") -> 0 | R31: Present: | S31: =COUNTIF(R29:S30,"✔") -> 0 | T31: Absent: | U31: =COUNTIF(T29:U30,"a") -> 0 | V31: Present: | W31: =COUNTIF(V29:W30,"✔") -> 0 | X31: Absent: | Y31: =COUNTIF(X29:Y30,"a") -> 0
B32: SIS MERCY; 0813 669 2754: [Headquarters Usher]; [OFF OMOZEE STREET, ERADIAWA / SAPELE ROAD BENIN CITY]
F34: Present: | G34: =COUNTIF(F32:G33,"✔") -> 0 | H34: Absent: | I34: =COUNTIF(H32:I33,"a") -> 0 | J34: Present: | K34: =COUNTIF(J32:K33,"✔") -> 0 | L34: Absent: | M34: =COUNTIF(L32:M33,"a") -> 0 | N34: Present: | O34: =COUNTIF(N32:O33,"✔") -> 0 | P34: Absent: | Q34: =COUNTIF(P32:Q33,"a") -> 0 | R34: Present: | S34: =COUNTIF(R32:S33,"✔") -> 0 | T34: Absent: | U34: =COUNTIF(T32:U33,"a") -> 0 | V34: Present: | W34: =COUNTIF(V32:W33,"✔") -> 0 | X34: Absent: | Y34: =COUNTIF(X32:Y33,"a") -> 0
B35: SIS GOD'S LOVE; 09072995858: [Headquarters Usher]; [OFF TONGO, ERADIAWA / SAPKONBA ROAD BENIN CITY]
F37: Present: | G37: =COUNTIF(F35:G36,"✔") -> 0 | H37: Absent: | I37: =COUNTIF(H35:I36,"a") -> 0 | J37: Present: | K37: =COUNTIF(J35:K36,"✔") -> 0 | L37: Absent: | M37: =COUNTIF(L35:M36,"a") -> 0 | N37: Present: | O37: =COUNTIF(N35:O36,"✔") -> 0 | P37: Absent: | Q37: =COUNTIF(P35:Q36,"a") -> 0 | R37: Present: | S37: =COUNTIF(R35:S36,"✔") -> 0 | T37: Absent: | U37: =COUNTIF(T35:U36,"a") -> 0 | V37: Present: | W37: =COUNTIF(V35:W36,"✔") -> 0 | X37: Absent: | Y37: =COUNTIF(X35:Y36,"a") -> 0
B38: MAMA MUDIA; 0907 197 1344: [Headquarters Usher]; [COUNTRY HOME ROAD, SAPELE ROAD BENIN CITY]
F40: Present: | G40: =COUNTIF(F38:G39,"✔") -> 0 | H40: Absent: | I40: =COUNTIF(H38:I39,"a") -> 0 | J40: Present: | K40: =COUNTIF(J38:K39,"✔") -> 0 | L40: Absent: | M40: =COUNTIF(L38:M39,"a") -> 0 | N40: Present: | O40: =COUNTIF(N38:O39,"✔") -> 0 | P40: Absent: | Q40: =COUNTIF(P38:Q39,"a") -> 0 | R40: Present: | S40: =COUNTIF(R38:S39,"✔") -> 0 | T40: Absent: | U40: =COUNTIF(T38:U39,"a") -> 0 | V40: Present: | W40: =COUNTIF(V38:W39,"✔") -> 0 | X40: Absent: | Y40: =COUNTIF(X38:Y39,"a") -> 0
B41: BRO. MONDAY OKPUNWAN; 09066459333: [Headquarters Usher]; [ BENIN CITY]
F43: Present: | G43: =COUNTIF(F41:G42,"✔") -> 0 | H43: Absent: | I43: =COUNTIF(H41:I42,"a") -> 0 | J43: Present: | K43: =COUNTIF(J41:K42,"✔") -> 0 | L43: Absent: | M43: =COUNTIF(L41:M42,"a") -> 0 | N43: Present: | O43: =COUNTIF(N41:O42,"✔") -> 0 | P43: Absent: | Q43: =COUNTIF(P41:Q42,"a") -> 0 | R43: Present: | S43: =COUNTIF(R41:S42,"✔") -> 0 | T43: Absent: | U43: =COUNTIF(T41:U42,"a") -> 0 | V43: Present: | W43: =COUNTIF(V41:W42,"✔") -> 0 | X43: Absent: | Y43: =COUNTIF(X41:Y42,"a") -> 0
B44: BRO. FRED OSAREKHOE; 08077035480: [Headquarters Usher]; [ BENIN CITY]
F46: Present: | G46: =COUNTIF(F44:G45,"✔") -> 0 | H46: Absent: | I46: =COUNTIF(H44:I45,"a") -> 0 | J46: Present: | K46: =COUNTIF(J44:K45,"✔") -> 0 | L46: Absent: | M46: =COUNTIF(L44:M45,"a") -> 0 | N46: Present: | O46: =COUNTIF(N44:O45,"✔") -> 0 | P46: Absent: | Q46: =COUNTIF(P44:Q45,"a") -> 0 | R46: Present: | S46: =COUNTIF(R44:S45,"✔") -> 0 | T46: Absent: | U46: =COUNTIF(T44:U45,"a") -> 0 | V46: Present: | W46: =COUNTIF(V44:W45,"✔") -> 0 | X46: Absent: | Y46: =COUNTIF(X44:Y45,"a") -> 0
B47: SIS. HAPPINESS; 09073677803: [Headquarters Usher]; [ BENIN CITY]
F49: Present: | G49: =COUNTIF(F47:G48,"✔") -> 0 | H49: Absent: | I49: =COUNTIF(H47:I48,"a") -> 0 | J49: Present: | K49: =COUNTIF(J47:K48,"✔") -> 0 | L49: Absent: | M49: =COUNTIF(L47:M48,"a") -> 0 | N49: Present: | O49: =COUNTIF(N47:O48,"✔") -> 0 | P49: Absent: | Q49: =COUNTIF(P47:Q48,"a") -> 0 | R49: Present: | S49: =COUNTIF(R47:S48,"✔") -> 0 | T49: Absent: | U49: =COUNTIF(T47:U48,"a") -> 0 | V49: Present: | W49: =COUNTIF(V47:W48,"✔") -> 0 | X49: Absent: | Y49: =COUNTIF(X47:Y48,"a") -> 0

Sheet MEDIA
B1: SPIRIT REALM CENTRE SUNDAY SERVICE ATTENDANCE TRACKER 2024
J2: PRESENT: | L2: ABSENT:
J3: ✔ | L3: A
B6: MEMBER'S INFORMATION | F6: 1ST SUN. 6/10/2024 | J6: 2ND SUN. 13/10/2024 | N6: 3RD SUN. 20/10/2024 | R6: 4TH SUN. 27/10/2024 | V6: 5 H SUN.
B8: IGWE DANIEL; 09069367219: [Headquarters Media]; [ADOLLOR STREET EVBUABOGUN]
F10: Present: | G10: =COUNTIF(F8:G9,"✔") -> 0 | H10: Absent: | I10: =COUNTIF(H8:I9,"a") -> 0 | J10: Present: | K10: =COUNTIF(J8:K9,"✔") -> 0 | L10: Absent: | M10: =COUNTIF(L8:M9,"a") -> 0 | N10: Present: | O10: =COUNTIF(N8:O9,"✔") -> 0 | P10: Absent: | Q10: =COUNTIF(P8:Q9,"a") -> 0 | R10: Present: | S10: =COUNTIF(R8:S9,"✔") -> 0 | T10: Absent: | U10: =COUNTIF(T8:U9,"a") -> 0 | V10: Present: | W10: =COUNTIF(V8:W9,"✔") -> 0 | X10: Absent: | Y10: =COUNTIF(X8:Y9,"a") -> 0
B11: ATESO AIGBEDION; 09069000699: [Headquarters Media]; [EVBUABOGUN]
F13: Present: | G13: =COUNTIF(F11:G12,"✔") -> 0 | H13: Absent: | I13: =COUNTIF(H11:I12,"a") -> 0 | J13: Present: | K13: =COUNTIF(J11:K12,"✔") -> 0 | L13: Absent: | M13: =COUNTIF(L11:M12,"a") -> 0 | N13: Present: | O13: =COUNTIF(N11:O12,"✔") -> 0 | P13: Absent: | Q13: =COUNTIF(P11:Q12,"a") -> 0 | R13: Present: | S13: =COUNTIF(R11:S12,"✔") -> 0 | T13: Absent: | U13: =COUNTIF(T11:U12,"a") -> 0 | V13: Present: | W13: =COUNTIF(V11:W12,"✔") -> 0 | X13: Absent: | Y13: =COUNTIF(X11:Y12,"a") -> 0
B14: IGWE SUNDAY EGWE; 09034210872: [Headquarters Media]; [Youth of Power and Glory]
F16: Present: | G16: =COUNTIF(F14:G15,"✔") -> 0 | H16: Absent: | I16: =COUNTIF(H14:I15,"a") -> 0 | J16: Present: | K16: =COUNTIF(J14:K15,"✔") -> 0 | L16: Absent: | M16: =COUNTIF(L14:M15,"a") -> 0 | N16: Present: | O16: =COUNTIF(N14:O15,"✔") -> 0 | P16: Absent: | Q16: =COUNTIF(P14:Q15,"a") -> 0 | R16: Present: | S16: =COUNTIF(R14:S15,"✔") -> 0 | T16: Absent: | U16: =COUNTIF(T14:U15,"a") -> 0 | V16: Present: | W16: =COUNTIF(V14:W15,"✔") -> 0 | X16: Absent: | Y16: =COUNTIF(X14:Y15,"a") -> 0
B17: MOSES EMMANUEL; 09163371049: [Headquarters Media]; [NO 5 UGIAGBE STREET OFF EREDIAUWA, SAPELE ROAD]
F19: Present: | G19: =COUNTIF(F17:G18,"✔") -> 0 | H19: Absent: | I19: =COUNTIF(H17:I18,"a") -> 0 | J19: Present: | K19: =COUNTIF(J17:K18,"✔") -> 0 | L19: Absent: | M19: =COUNTIF(L17:M18,"a") -> 0 | N19: Present: | O19: =COUNTIF(N17:O18,"✔") -> 0 | P19: Absent: | Q19: =COUNTIF(P17:Q18,"a") -> 0 | R19: Present: | S19: =COUNTIF(R17:S18,"✔") -> 0 | T19: Absent: | U19: =COUNTIF(T17:U18,"a") -> 0 | V19: Present: | W19: =COUNTIF(V17:W18,"✔") -> 0 | X19: Absent: | Y19: =COUNTIF(X17:Y18,"a") -> 0
B20: BRO LUCKY; 09060597582: [Headquarters Media]; [address]
F22: Present: | G22: =COUNTIF(F20:G21,"✔") -> 0 | H22: Absent: | I22: =COUNTIF(H20:I21,"a") -> 0 | J22: Present: | K22: =COUNTIF(J20:K21,"✔") -> 0 | L22: Absent: | M22: =COUNTIF(L20:M21,"a") -> 0 | N22: Present: | O22: =COUNTIF(N20:O21,"✔") -> 0 | P22: Absent: | Q22: =COUNTIF(P20:Q21,"a") -> 0 | R22: Present: | S22: =COUNTIF(R20:S21,"✔") -> 0 | T22: Absent: | U22: =COUNTIF(T20:U21,"a") -> 0 | V22: Present: | W22: =COUNTIF(V20:W21,"✔") -> 0 | X22: Absent: | Y22: =COUNTIF(X20:Y21,"a") -> 0

Sheet SECURITY
B1: SPIRIT REALM CENTRE SUNDAY SERVICE ATTENDANCE TRACKER 2024
J2: PRESENT: | L2: ABSENT:
J3: ✔ | L3: A
B6: MEMBER'S INFORMATION | F6: 1ST SUN. 6/10/2024 | J6: 2ND SUN. 13/10/2024 | N6: 3RD SUN. 20/10/2024 | R6: 4TH SUN. 27/10/2024 | V6: 5 H SUN.
B8: BRO CHARLES AGBONKINA: [Headquarters Security]; [Address]
F10: Present: | G10: =COUNTIF(F8:G9,"✔") -> 0 | H10: Absent: | I10: =COUNTIF(H8:I9,"a") -> 0 | J10: Present: | K10: =COUNTIF(J8:K9,"✔") -> 0 | L10: Absent: | M10: =COUNTIF(L8:M9,"a") -> 0 | N10: Present: | O10: =COUNTIF(N8:O9,"✔") -> 0 | P10: Absent: | Q10: =COUNTIF(P8:Q9,"a") -> 0 | R10: Present: | S10: =COUNTIF(R8:S9,"✔") -> 0 | T10: Absent: | U10: =COUNTIF(T8:U9,"a") -> 0 | V10: Present: | W10: =COUNTIF(V8:W9,"✔") -> 0 | X10: Absent: | Y10: =COUNTIF(X8:Y9,"a") -> 0
B11: BRO SAMUEL BASSEY: [Headquarters Security]; [Address]
F13: Present: | G13: =COUNTIF(F11:G12,"✔") -> 0 | H13: Absent: | I13: =COUNTIF(H11:I12,"a") -> 0 | J13: Present: | K13: =COUNTIF(J11:K12,"✔") -> 0 | L13: Absent: | M13: =COUNTIF(L11:M12,"a") -> 0 | N13: Present: | O13: =COUNTIF(N11:O12,"✔") -> 0 | P13: Absent: | Q13: =COUNTIF(P11:Q12,"a") -> 0 | R13: Present: | S13: =COUNTIF(R11:S12,"✔") -> 0 | T13: Absent: | U13: =COUNTIF(T11:U12,"a") -> 0 | V13: Present: | W13: =COUNTIF(V11:W12,"✔") -> 0 | X13: Absent: | Y13: =COUNTIF(X11:Y12,"a") -> 0
B14: PAUL O. ASEMOTA: [Headquarters Security]; [Address]
F16: Present: | G16: =COUNTIF(F14:G15,"✔") -> 0 | H16: Absent: | I16: =COUNTIF(H14:I15,"a") -> 0 | J16: Present: | K16: =COUNTIF(J14:K15,"✔") -> 0 | L16: Absent: | M16: =COUNTIF(L14:M15,"a") -> 0 | N16: Present: | O16: =COUNTIF(N14:O15,"✔") -> 0 | P16: Absent: | Q16: =COUNTIF(P14:Q15,"a") -> 0 | R16: Present: | S16: =COUNTIF(R14:S15,"✔") -> 0 | T16: Absent: | U16: =COUNTIF(T14:U15,"a") -> 0 | V16: Present: | W16: =COUNTIF(V14:W15,"✔") -> 0 | X16: Absent: | Y16: =COUNTIF(X14:Y15,"a") -> 0
B17: UZOMA MADUKA: [Headquarters Security]; [Address]
F19: Present: | G19: =COUNTIF(F17:G18,"✔") -> 0 | H19: Absent: | I19: =COUNTIF(H17:I18,"a") -> 0 | J19: Present: | K19: =COUNTIF(J17:K18,"✔") -> 0 | L19: Absent: | M19: =COUNTIF(L17:M18,"a") -> 0 | N19: Present: | O19: =COUNTIF(N17:O18,"✔") -> 0 | P19: Absent: | Q19: =COUNTIF(P17:Q18,"a") -> 0 | R19: Present: | S19: =COUNTIF(R17:S18,"✔") -> 0 | T19: Absent: | U19: =COUNTIF(T17:U18,"a") -> 0 | V19: Present: | W19: =COUNTIF(V17:W18,"✔") -> 0 | X19: Absent: | Y19: =COUNTIF(X17:Y18,"a") -> 0
B20: MRS. ELO: [Headquarters Security]; [Address]
F22: Present: | G22: =COUNTIF(F20:G21,"✔") -> 0 | H22: Absent: | I22: =COUNTIF(H20:I21,"a") -> 0 | J22: Present: | K22: =COUNTIF(J20:K21,"✔") -> 0 | L22: Absent: | M22: =COUNTIF(L20:M21,"a") -> 0 | N22: Present: | O22: =COUNTIF(N20:O21,"✔") -> 0 | P22: Absent: | Q22: =COUNTIF(P20:Q21,"a") -> 0 | R22: Present: | S22: =COUNTIF(R20:S21,"✔") -> 0 | T22: Absent: | U22: =COUNTIF(T20:U21,"a") -> 0 | V22: Present: | W22: =COUNTIF(V20:W21,"✔") -> 0 | X22: Absent: | Y22: =COUNTIF(X20:Y21,"a") -> 0
B23: BROTHER BEN: [Headquarters Security]; [Address]
F25: Present: | G25: =COUNTIF(F23:G24,"✔") -> 0 | H25: Absent: | I25: =COUNTIF(H23:I24,"a") -> 0 | J25: Present: | K25: =COUNTIF(J23:K24,"✔") -> 0 | L25: Absent: | M25: =COUNTIF(L23:M24,"a") -> 0 | N25: Present: | O25: =COUNTIF(N23:O24,"✔") -> 0 | P25: Absent: | Q25: =COUNTIF(P23:Q24,"a") -> 0 | R25: Present: | S25: =COUNTIF(R23:S24,"✔") -> 0 | T25: Absent: | U25: =COUNTIF(T23:U24,"a") -> 0 | V25: Present: | W25: =COUNTIF(V23:W24,"✔") -> 0 | X25: Absent: | Y25: =COUNTIF(X23:Y24,"a") -> 0

Sheet PRAYER GROUP
B1: SPIRIT REALM CENTRE SUNDAY SERVICE ATTENDANCE TRACKER 2024
J2: PRESENT: | L2: ABSENT:
J3: ✔ | L3: A
B6: MEMBER'S INFORMATION | F6: 1ST SUN. 6/10/2024 | J6: 2ND SUN. 13/10/2024 | N6: 3RD SUN. 20/10/2024 | R6: 4TH SUN. 27/10/2024 | V6: 5 H SUN.
B8: MIN VICTOR; 0810507062: [Headquarters Prayer]; [Address]
F10: Present: | G10: =COUNTIF(F8:G9,"✔") -> 0 | H10: Absent: | I10: =COUNTIF(H8:I9,"a") -> 0 | J10: Present: | K10: =COUNTIF(J8:K9,"✔") -> 0 | L10: Absent: | M10: =COUNTIF(L8:M9,"a") -> 0 | N10: Present: | O10: =COUNTIF(N8:O9,"✔") -> 0 | P10: Absent: | Q10: =COUNTIF(P8:Q9,"a") -> 0 | R10: Present: | S10: =COUNTIF(R8:S9,"✔") -> 0 | T10: Absent: | U10: =COUNTIF(T8:U9,"a") -> 0 | V10: Present: | W10: =COUNTIF(V8:W9,"✔") -> 0 | X10: Absent: | Y10: =COUNTIF(X8:Y9,"a") -> 0
B11: MIN BRIGHT; 08052155988: [Headquarters Prayer]; [Address]
F13: Present: | G13: =COUNTIF(F11:G12,"✔") -> 0 | H13: Absent: | I13: =COUNTIF(H11:I12,"a") -> 0 | J13: Present: | K13: =COUNTIF(J11:K12,"✔") -> 0 | L13: Absent: | M13: =COUNTIF(L11:M12,"a") -> 0 | N13: Present: | O13: =COUNTIF(N11:O12,"✔") -> 0 | P13: Absent: | Q13: =COUNTIF(P11:Q12,"a") -> 0 | R13: Present: | S13: =COUNTIF(R11:S12,"✔") -> 0 | T13: Absent: | U13: =COUNTIF(T11:U12,"a") -> 0 | V13: Present: | W13: =COUNTIF(V11:W12,"✔") -> 0 | X13: Absent: | Y13: =COUNTIF(X11:Y12,"a") -> 0
B14: SIS STELLA: [Headquarters Prayer]; [Address]
F16: Present: | G16: =COUNTIF(F14:G15,"✔") -> 0 | H16: Absent: | I16: =COUNTIF(H14:I15,"a") -> 0 | J16: Present: | K16: =COUNTIF(J14:K15,"✔") -> 0 | L16: Absent: | M16: =COUNTIF(L14:M15,"a") -> 0 | N16: Present: | O16: =COUNTIF(N14:O15,"✔") -> 0 | P16: Absent: | Q16: =COUNTIF(P14:Q15,"a") -> 0 | R16: Present: | S16: =COUNTIF(R14:S15,"✔") -> 0 | T16: Absent: | U16: =COUNTIF(T14:U15,"a") -> 0 | V16: Present: | W16: =COUNTIF(V14:W15,"✔") -> 0 | X16: Absent: | Y16: =COUNTIF(X14:Y15,"a") -> 0
B17: SIS JESSICA: [Headquarters Prayer]; [Address]
F19: Present: | G19: =COUNTIF(F17:G18,"✔") -> 0 | H19: Absent: | I19: =COUNTIF(H17:I18,"a") -> 0 | J19: Present: | K19: =COUNTIF(J17:K18,"✔") -> 0 | L19: Absent: | M19: =COUNTIF(L17:M18,"a") -> 0 | N19: Present: | O19: =COUNTIF(N17:O18,"✔") -> 0 | P19: Absent: | Q19: =COUNTIF(P17:Q18,"a") -> 0 | R19: Present: | S19: =COUNTIF(R17:S18,"✔") -> 0 | T19: Absent: | U19: =COUNTIF(T17:U18,"a") -> 0 | V19: Present: | W19: =COUNTIF(V17:W18,"✔") -> 0 | X19: Absent: | Y19: =COUNTIF(X17:Y18,"a") -> 0
B20: BRO EHIS: [Headquarters Prayer]; [Address]
F22: Present: | G22: =COUNTIF(F20:G21,"✔") -> 0 | H22: Absent: | I22: =COUNTIF(H20:I21,"a") -> 0 | J22: Present: | K22: =COUNTIF(J20:K21,"✔") -> 0 | L22: Absent: | M22: =COUNTIF(L20:M21,"a") -> 0 | N22: Present: | O22: =COUNTIF(N20:O21,"✔") -> 0 | P22: Absent: | Q22: =COUNTIF(P20:Q21,"a") -> 0 | R22: Present: | S22: =COUNTIF(R20:S21,"✔") -> 0 | T22: Absent: | U22: =COUNTIF(T20:U21,"a") -> 0 | V22: Present: | W22: =COUNTIF(V20:W21,"✔") -> 0 | X22: Absent: | Y22: =COUNTIF(X20:Y21,"a") -> 0
B23: BRO BENARD: [Headquarters Prayer]; [Address]
F25: Present: | G25: =COUNTIF(F23:G24,"✔") -> 0 | H25: Absent: | I25: =COUNTIF(H23:I24,"a") -> 0 | J25: Present: | K25: =COUNTIF(J23:K24,"✔") -> 0 | L25: Absent: | M25: =COUNTIF(L23:M24,"a") -> 0 | N25: Present: | O25: =COUNTIF(N23:O24,"✔") -> 0 | P25: Absent: | Q25: =COUNTIF(P23:Q24,"a") -> 0 | R25: Present: | S25: =COUNTIF(R23:S24,"✔") -> 0 | T25: Absent: | U25: =COUNTIF(T23:U24,"a") -> 0 | V25: Present: | W25: =COUNTIF(V23:W24,"✔") -> 0 | X25: Absent: | Y25: =COUNTIF(X23:Y24,"a") -> 0
B26: BRO GABRIEL: [Headquarters Prayer]; [Address]
F28: Present: | G28: =COUNTIF(F26:G27,"✔") -> 0 | H28: Absent: | I28: =COUNTIF(H26:I27,"a") -> 0 | J28: Present: | K28: =COUNTIF(J26:K27,"✔") -> 0 | L28: Absent: | M28: =COUNTIF(L26:M27,"a") -> 0 | N28: Present: | O28: =COUNTIF(N26:O27,"✔") -> 0 | P28: Absent: | Q28: =COUNTIF(P26:Q27,"a") -> 0 | R28: Present: | S28: =COUNTIF(R26:S27,"✔") -> 0 | T28: Absent: | U28: =COUNTIF(T26:U27,"a") -> 0 | V28: Present: | W28: =COUNTIF(V26:W27,"✔") -> 0 | X28: Absent: | Y28: =COUNTIF(X26:Y27,"a") -> 0
B29: BRO OSAGIE: [Headquarters Prayer]; [Address]
F31: Present: | G31: =COUNTIF(F29:G30,"✔") -> 0 | H31: Absent: | I31: =COUNTIF(H29:I30,"a") -> 0 | J31: Present: | K31: =COUNTIF(J29:K30,"✔") -> 0 | L31: Absent: | M31: =COUNTIF(L29:M30,"a") -> 0 | N31: Present: | O31: =COUNTIF(N29:O30,"✔") -> 0 | P31: Absent: | Q31: =COUNTIF(P29:Q30,"a") -> 0 | R31: Present: | S31: =COUNTIF(R29:S30,"✔") -> 0 | T31: Absent: | U31: =COUNTIF(T29:U30,"a") -> 0 | V31: Present: | W31: =COUNTIF(V29:W30,"✔") -> 0 | X31: Absent: | Y31: =COUNTIF(X29:Y30,"a") -> 0

Sheet GODLY ACTION
B1: SPIRIT REALM CENTRE SUNDAY SERVICE ATTENDANCE TRACKER 2024
J2: PRESENT: | L2: ABSENT:
J3: ✔ | L3: A
B6: MEMBER'S INFORMATION | F6: 1ST SUN. 6/10/2024 | J6: 2ND SUN. 13/10/2024 | N6: 3RD SUN. 20/10/2024 | R6: 4TH SUN. 27/10/2024 | V6: 5 H SUN.
B8: MIN VICTOR; 0810507062: [Headquarters Godly Action]; [Address]
F10: Present: | G10: =COUNTIF(F8:G9,"✔") -> 0 | H10: Absent: | I10: =COUNTIF(H8:I9,"a") -> 0 | J10: Present: | K10: =COUNTIF(J8:K9,"✔") -> 0 | L10: Absent: | M10: =COUNTIF(L8:M9,"a") -> 0 | N10: Present: | O10: =COUNTIF(N8:O9,"✔") -> 0 | P10: Absent: | Q10: =COUNTIF(P8:Q9,"a") -> 0 | R10: Present: | S10: =COUNTIF(R8:S9,"✔") -> 0 | T10: Absent: | U10: =COUNTIF(T8:U9,"a") -> 0 | V10: Present: | W10: =COUNTIF(V8:W9,"✔") -> 0 | X10: Absent: | Y10: =COUNTIF(X8:Y9,"a") -> 0
B11: MIN BRIGHT; 08052155988: [Headquarters Godly Action]; [Address]
F13: Present: | G13: =COUNTIF(F11:G12,"✔") -> 0 | H13: Absent: | I13: =COUNTIF(H11:I12,"a") -> 0 | J13: Present: | K13: =COUNTIF(J11:K12,"✔") -> 0 | L13: Absent: | M13: =COUNTIF(L11:M12,"a") -> 0 | N13: Present: | O13: =COUNTIF(N11:O12,"✔") -> 0 | P13: Absent: | Q13: =COUNTIF(P11:Q12,"a") -> 0 | R13: Present: | S13: =COUNTIF(R11:S12,"✔") -> 0 | T13: Absent: | U13: =COUNTIF(T11:U12,"a") -> 0 | V13: Present: | W13: =COUNTIF(V11:W12,"✔") -> 0 | X13: Absent: | Y13: =COUNTIF(X11:Y12,"a") -> 0
B14: BRO LUCKY; 08116110454: [Headquarters Godly Action]; [Address]
F16: Present: | G16: =COUNTIF(F14:G15,"✔") -> 0 | H16: Absent: | I16: =COUNTIF(H14:I15,"a") -> 0 | J16: Present: | K16: =COUNTIF(J14:K15,"✔") -> 0 | L16: Absent: | M16: =COUNTIF(L14:M15,"a") -> 0 | N16: Present: | O16: =COUNTIF(N14:O15,"✔") -> 0 | P16: Absent: | Q16: =COUNTIF(P14:Q15,"a") -> 0 | R16: Present: | S16: =COUNTIF(R14:S15,"✔") -> 0 | T16: Absent: | U16: =COUNTIF(T14:U15,"a") -> 0 | V16: Present: | W16: =COUNTIF(V14:W15,"✔") -> 0 | X16: Absent: | Y16: =COUNTIF(X14:Y15,"a") -> 0
B17: BRO MORRIS; 08071978244: [Headquarters Godly Action]; [Address]
F19: Present: | G19: =COUNTIF(F17:G18,"✔") -> 0 | H19: Absent: | I19: =COUNTIF(H17:I18,"a") -> 0 | J19: Present: | K19: =COUNTIF(J17:K18,"✔") -> 0 | L19: Absent: | M19: =COUNTIF(L17:M18,"a") -> 0 | N19: Present: | O19: =COUNTIF(N17:O18,"✔") -> 0 | P19: Absent: | Q19: =COUNTIF(P17:Q18,"a") -> 0 | R19: Present: | S19: =COUNTIF(R17:S18,"✔") -> 0 | T19: Absent: | U19: =COUNTIF(T17:U18,"a") -> 0 | V19: Present: | W19: =COUNTIF(V17:W18,"✔") -> 0 | X19: Absent: | Y19: =COUNTIF(X17:Y18,"a") -> 0
B20: BRO GABRIEL; 09118794939: [Headquarters Godly Action]; [Address]
F22: Present: | G22: =COUNTIF(F20:G21,"✔") -> 0 | H22: Absent: | I22: =COUNTIF(H20:I21,"a") -> 0 | J22: Present: | K22: =COUNTIF(J20:K21,"✔") -> 0 | L22: Absent: | M22: =COUNTIF(L20:M21,"a") -> 0 | N22: Present: | O22: =COUNTIF(N20:O21,"✔") -> 0 | P22: Absent: | Q22: =COUNTIF(P20:Q21,"a") -> 0 | R22: Present: | S22: =COUNTIF(R20:S21,"✔") -> 0 | T22: Absent: | U22: =COUNTIF(T20:U21,"a") -> 0 | V22: Present: | W22: =COUNTIF(V20:W21,"✔") -> 0 | X22: Absent: | Y22: =COUNTIF(X20:Y21,"a") -> 0
B23: BRO GOD'S POWER; 09011402427: [Headquarters Godly Action]; [Address]
F25: Present: | G25: =COUNTIF(F23:G24,"✔") -> 0 | H25: Absent: | I25: =COUNTIF(H23:I24,"a") -> 0 | J25: Present: | K25: =COUNTIF(J23:K24,"✔") -> 0 | L25: Absent: | M25: =COUNTIF(L23:M24,"a") -> 0 | N25: Present: | O25: =COUNTIF(N23:O24,"✔") -> 0 | P25: Absent: | Q25: =COUNTIF(P23:Q24,"a") -> 0 | R25: Present: | S25: =COUNTIF(R23:S24,"✔") -> 0 | T25: Absent: | U25: =COUNTIF(T23:U24,"a") -> 0 | V25: Present: | W25: =COUNTIF(V23:W24,"✔") -> 0 | X25: Absent: | Y25: =COUNTIF(X23:Y24,"a") -> 0
B26: BRO VICTORY; 0911295701: [Headquarters Godly Action]; [Address]
F28: Present: | G28: =COUNTIF(F26:G27,"✔") -> 0 | H28: Absent: | I28: =COUNTIF(H26:I27,"a") -> 0 | J28: Present: | K28: =COUNTIF(J26:K27,"✔") -> 0 | L28: Absent: | M28: =COUNTIF(L26:M27,"a") -> 0 | N28: Present: | O28: =COUNTIF(N26:O27,"✔") -> 0 | P28: Absent: | Q28: =COUNTIF(P26:Q27,"a") -> 0 | R28: Present: | S28: =COUNTIF(R26:S27,"✔") -> 0 | T28: Absent: | U28: =COUNTIF(T26:U27,"a") -> 0 | V28: Present: | W28: =COUNTIF(V26:W27,"✔") -> 0 | X28: Absent: | Y28: =COUNTIF(X26:Y27,"a") -> 0
B29: SIS CHARITY; 07018582492: [Headquarters Godly Action]; [Address]
F31: Present: | G31: =COUNTIF(F29:G30,"✔") -> 0 | H31: Absent: | I31: =COUNTIF(H29:I30,"a") -> 0 | J31: Present: | K31: =COUNTIF(J29:K30,"✔") -> 0 | L31: Absent: | M31: =COUNTIF(L29:M30,"a") -> 0 | N31: Present: | O31: =COUNTIF(N29:O30,"✔") -> 0 | P31: Absent: | Q31: =COUNTIF(P29:Q30,"a") -> 0 | R31: Present: | S31: =COUNTIF(R29:S30,"✔") -> 0 | T31: Absent: | U31: =COUNTIF(T29:U30,"a") -> 0 | V31: Present: | W31: =COUNTIF(V29:W30,"✔") -> 0 | X31: Absent: | Y31: =COUNTIF(X29:Y30,"a") -> 0
B32: SIS FAVOUR; 09156464691: [Headquarters Godly Action]; [Address]
F34: Present: | G34: =COUNTIF(F32:G33,"✔") -> 0 | H34: Absent: | I34: =COUNTIF(H32:I33,"a") -> 0 | J34: Present: | K34: =COUNTIF(J32:K33,"✔") -> 0 | L34: Absent: | M34: =COUNTIF(L32:M33,"a") -> 0 | N34: Present: | O34: =COUNTIF(N32:O33,"✔") -> 0 | P34: Absent: | Q34: =COUNTIF(P32:Q33,"a") -> 0 | R34: Present: | S34: =COUNTIF(R32:S33,"✔") -> 0 | T34: Absent: | U34: =COUNTIF(T32:U33,"a") -> 0 | V34: Present: | W34: =COUNTIF(V32:W33,"✔") -> 0 | X34: Absent: | Y34: =COUNTIF(X32:Y33,"a") -> 0
B35: SIS GRACE; 09032441393: [Headquarters Godly Action]; [Address]
F37: Present: | G37: =COUNTIF(F35:G36,"✔") -> 0 | H37: Absent: | I37: =COUNTIF(H35:I36,"a") -> 0 | J37: Present: | K37: =COUNTIF(J35:K36,"✔") -> 0 | L37: Absent: | M37: =COUNTIF(L35:M36,"a") -> 0 | N37: Present: | O37: =COUNTIF(N35:O36,"✔") -> 0 | P37: Absent: | Q37: =COUNTIF(P35:Q36,"a") -> 0 | R37: Present: | S37: =COUNTIF(R35:S36,"✔") -> 0 | T37: Absent: | U37: =COUNTIF(T35:U36,"a") -> 0 | V37: Present: | W37: =COUNTIF(V35:W36,"✔") -> 0 | X37: Absent: | Y37: =COUNTIF(X35:Y36,"a") -> 0
B38: SIS JOY; 09165656495: [Headquarters Godly Action]; [Address]
F40: Present: | G40: =COUNTIF(F38:G39,"✔") -> 0 | H40: Absent: | I40: =COUNTIF(H38:I39,"a") -> 0 | J40: Present: | K40: =COUNTIF(J38:K39,"✔") -> 0 | L40: Absent: | M40: =COUNTIF(L38:M39,"a") -> 0 | N40: Present: | O40: =COUNTIF(N38:O39,"✔") -> 0 | P40: Absent: | Q40: =COUNTIF(P38:Q39,"a") -> 0 | R40: Present: | S40: =COUNTIF(R38:S39,"✔") -> 0 | T40: Absent: | U40: =COUNTIF(T38:U39,"a") -> 0 | V40: Present: | W40: =COUNTIF(V38:W39,"✔") -> 0 | X40: Absent: | Y40: =COUNTIF(X38:Y39,"a") -> 0
B41: BRO DAN; 09069367216: [Headquarters Godly Action]; [Address]
F43: Present: | G43: =COUNTIF(F41:G42,"✔") -> 0 | H43: Absent: | I43: =COUNTIF(H41:I42,"a") -> 0 | J43: Present: | K43: =COUNTIF(J41:K42,"✔") -> 0 | L43: Absent: | M43: =COUNTIF(L41:M42,"a") -> 0 | N43: Present: | O43: =COUNTIF(N41:O42,"✔") -> 0 | P43: Absent: | Q43: =COUNTIF(P41:Q42,"a") -> 0 | R43: Present: | S43: =COUNTIF(R41:S42,"✔") -> 0 | T43: Absent: | U43: =COUNTIF(T41:U42,"a") -> 0 | V43: Present: | W43: =COUNTIF(V41:W42,"✔") -> 0 | X43: Absent: | Y43: =COUNTIF(X41:Y42,"a") -> 0
B44: SIS COURAGE; 09052268276: [Headquarters Godly Action]; [Address]
F46: Present: | G46: =COUNTIF(F44:G45,"✔") -> 0 | H46: Absent: | I46: =COUNTIF(H44:I45,"a") -> 0 | J46: Present: | K46: =COUNTIF(J44:K45,"✔") -> 0 | L46: Absent: | M46: =COUNTIF(L44:M45,"a") -> 0 | N46: Present: | O46: =COUNTIF(N44:O45,"✔") -> 0 | P46: Absent: | Q46: =COUNTIF(P44:Q45,"a") -> 0 | R46: Present: | S46: =COUNTIF(R44:S45,"✔") -> 0 | T46: Absent: | U46: =COUNTIF(T44:U45,"a") -> 0 | V46: Present: | W46: =COUNTIF(V44:W45,"✔") -> 0 | X46: Absent: | Y46: =COUNTIF(X44:Y45,"a") -> 0
B47: BRO MARVELOUS; 09011816906: [Headquarters Godly Action]; [Address]
F49: Present: | G49: =COUNTIF(F47:G48,"✔") -> 0 | H49: Absent: | I49: =COUNTIF(H47:I48,"a") -> 0 | J49: Present: | K49: =COUNTIF(J47:K48,"✔") -> 0 | L49: Absent: | M49: =COUNTIF(L47:M48,"a") -> 0 | N49: Present: | O49: =COUNTIF(N47:O48,"✔") -> 0 | P49: Absent: | Q49: =COUNTIF(P47:Q48,"a") -> 0 | R49: Present: | S49: =COUNTIF(R47:S48,"✔") -> 0 | T49: Absent: | U49: =COUNTIF(T47:U48,"a") -> 0 | V49: Present: | W49: =COUNTIF(V47:W48,"✔") -> 0 | X49: Absent: | Y49: =COUNTIF(X47:Y48,"a") -> 0
B50: BRO OSA-GREAT; 07010707729: [Headquarters Godly Action]; [Address]
F52: Present: | G52: =COUNTIF(F50:G51,"✔") -> 0 | H52: Absent: | I52: =COUNTIF(H50:I51,"a") -> 0 | J52: Present: | K52: =COUNTIF(J50:K51,"✔") -> 0 | L52: Absent: | M52: =COUNTIF(L50:M51,"a") -> 0 | N52: Present: | O52: =COUNTIF(N50:O51,"✔") -> 0 | P52: Absent: | Q52: =COUNTIF(P50:Q51,"a") -> 0 | R52: Present: | S52: =COUNTIF(R50:S51,"✔") -> 0 | T52: Absent: | U52: =COUNTIF(T50:U51,"a") -> 0 | V52: Present: | W52: =COUNTIF(V50:W51,"✔") -> 0 | X52: Absent: | Y52: =COUNTIF(X50:Y51,"a") -> 0
B53: BRO OSA-WEALTH; 08023656579: [Headquarters Godly Action]; [Address]
F55: Present: | G55: =COUNTIF(F53:G54,"✔") -> 0 | H55: Absent: | I55: =COUNTIF(H53:I54,"a") -> 0 | J55: Present: | K55: =COUNTIF(J53:K54,"✔") -> 0 | L55: Absent: | M55: =COUNTIF(L53:M54,"a") -> 0 | N55: Present: | O55: =COUNTIF(N53:O54,"✔") -> 0 | P55: Absent: | Q55: =COUNTIF(P53:Q54,"a") -> 0 | R55: Present: | S55: =COUNTIF(R53:S54,"✔") -> 0 | T55: Absent: | U55: =COUNTIF(T53:U54,"a") -> 0 | V55: Present: | W55: =COUNTIF(V53:W54,"✔") -> 0 | X55: Absent: | Y55: =COUNTIF(X53:Y54,"a") -> 0
B56: BRO OSA-LIGHT: [Headquarters Godly Action]; [Address]
F58: Present: | G58: =COUNTIF(F56:G57,"✔") -> 0 | H58: Absent: | I58: =COUNTIF(H56:I57,"a") -> 0 | J58: Present: | K58: =COUNTIF(J56:K57,"✔") -> 0 | L58: Absent: | M58: =COUNTIF(L56:M57,"a") -> 0 | N58: Present: | O58: =COUNTIF(N56:O57,"✔") -> 0 | P58: Absent: | Q58: =COUNTIF(P56:Q57,"a") -> 0 | R58: Present: | S58: =COUNTIF(R56:S57,"✔") -> 0 | T58: Absent: | U58: =COUNTIF(T56:U57,"a") -> 0 | V58: Present: | W58: =COUNTIF(V56:W57,"✔") -> 0 | X58: Absent: | Y58: =COUNTIF(X56:Y57,"a") -> 0
B59: BRO OSA-GREAT; 07010707729: [Headquarters Godly Action]; [Address]
F61: Present: | G61: =COUNTIF(F59:G60,"✔") -> 0 | H61: Absent: | I61: =COUNTIF(H59:I60,"a") -> 0 | J61: Present: | K61: =COUNTIF(J59:K60,"✔") -> 0 | L61: Absent: | M61: =COUNTIF(L59:M60,"a") -> 0 | N61: Present: | O61: =COUNTIF(N59:O60,"✔") -> 0 | P61: Absent: | Q61: =COUNTIF(P59:Q60,"a") -> 0 | R61: Present: | S61: =COUNTIF(R59:S60,"✔") -> 0 | T61: Absent: | U61: =COUNTIF(T59:U60,"a") -> 0 | V61: Present: | W61: =COUNTIF(V59:W60,"✔") -> 0 | X61: Absent: | Y61: =COUNTIF(X59:Y60,"a") -> 0
...

Sheet COUNSELLING 

Sheet SANCTUARY

Sheet EWEKA
A2: EWEKA EXTENSION
A4: PST. RAMANUS
A6: 9032761666
A8: SISTER JOVITA
A10: 7041854892
A12: DCN. ESTON
A14: 8034747107
A16: SISTER JULIET YAKUBU
A18: 7081243374
A20: BRO. PIUS TITANA
A22: 7032841227
A24: SISTER VITA
A26: 7038376555
A28: EPA OMOREGBON
A30: 7057422976
A32: SISTER LOVETH GODWIN
A34: 9139288465
A36: SISTER JOY ONI
A38: 9163234837
A40: SISTER ESTHER OSHIOREMO
A42: 7045864651
A44: SISTER VICTORY CHRISTIAN
A46: SISTER RUTH CHRISTIAN
A48: BRO. MICHEAL CHRISTIAN
A50: 8105389768
A52: BRO. ANDREW EMMANUEL
A54: 8064265810
A56: SISTER EUNICE YAKUBU
A58: 9123167764
A60: SISTER VIOLET AGBOW
A62: 9063501727
A64: SISTER GIFT SUNDAY
A66: 8023045591
A68: SISTER VICTORY SAMUEL
A70: NIL
A72: IRREGULAR MEMBERS
A74: SISTER JOY SAMUEL 08082046262
A76: SISTER ESTHER LUCKY 07056141005
A78: SISTER JENNIFER IMEREMUN 0906442700
A80: SISTER BLESSING ISAAC 0915414497
...

Sheet ABSENT
A1: ABSENT MEMBERS
A2: 45571
A3: PRAYER GROUP
A4: SIS STELLA
A5: SIS JESSICA
A6: BRO EHIS
A7: BRO GABRIEL
A9: GODLY ACTION
A10: BRO GABRIEL
A11: 45578
A12: MEN OF IMPACT
A13: Brother Charles
A15: Brother Ik njoku
A17: Brother Stanley
A19: Brother Paul
A21: Brother Esosa
A23: Brother uzoma
A25: Brother Kennedy
A27: Brother Solomon
A29: Brother goodnews
A31: Brother ejiro
A33: Brother Ehis
A35: Bro. Gabriel 09118794939

Sheet Sheet9

Sheet Sheet10
